{"name": "test_fail", "status": "failed", "statusDetails": {"message": "AssertionError: assert False", "trace": "self = <TestCases.test_login.TestLogin object at 0x00000170AB3EF400>\n\n    @pytest.mark.fail\n    def test_fail(self):\n>       assert False\nE       assert False\n\nTestCases\\test_login.py:79: AssertionError"}, "start": 1594722845939, "stop": 1594722845939, "uuid": "b17d6164-b573-494b-b918-8ece4a136dbf", "historyId": "28e9c5ffc75a164b5fc32ce5123d15e4", "testCaseId": "7c7d6ede0f82a234c3e8e9b8a768984e", "fullName": "TestCases.test_login.TestLogin#test_fail", "labels": [{"name": "tag", "value": "@pytest.mark.usefixtures('init_driver')"}, {"name": "tag", "value": "fail"}, {"name": "tag", "value": "login"}, {"name": "parentSuite", "value": "TestCases"}, {"name": "suite", "value": "test_login"}, {"name": "subSuite", "value": "TestLogin"}, {"name": "host", "value": "DESKTOP-KFH4O7N"}, {"name": "thread", "value": "25984-MainThread"}, {"name": "framework", "value": "pytest"}, {"name": "language", "value": "cpython3"}, {"name": "package", "value": "TestCases.test_login"}]}